2020-04-22 14:16:48,622 ERROR: Exception on /labApp/quality_control [GET] [in c:\mamp\htdocs\labapp\venv\lib\site-packages\flask\app.py:1892]
Traceback (most recent call last):
  File "c:\mamp\htdocs\labapp\venv\lib\site-packages\sqlalchemy\util\_collections.py", line 1030, in __call__
    return self.registry[key]
KeyError: 14572

During handling of the above exception, another exception occurred:

Traceback (most recent call last):
  File "c:\mamp\htdocs\labapp\venv\lib\site-packages\flask\app.py", line 2447, in wsgi_app
    response = self.full_dispatch_request()
  File "c:\mamp\htdocs\labapp\venv\lib\site-packages\flask\app.py", line 1952, in full_dispatch_request
    rv = self.handle_user_exception(e)
  File "c:\mamp\htdocs\labapp\venv\lib\site-packages\flask_cors\extension.py", line 161, in wrapped_function
    return cors_after_request(app.make_response(f(*args, **kwargs)))
  File "c:\mamp\htdocs\labapp\venv\lib\site-packages\flask\app.py", line 1821, in handle_user_exception
    reraise(exc_type, exc_value, tb)
  File "c:\mamp\htdocs\labapp\venv\lib\site-packages\flask\_compat.py", line 39, in reraise
    raise value
  File "c:\mamp\htdocs\labapp\venv\lib\site-packages\flask\app.py", line 1948, in full_dispatch_request
    rv = self.preprocess_request()
  File "c:\mamp\htdocs\labapp\venv\lib\site-packages\flask\app.py", line 2242, in preprocess_request
    rv = func()
  File "C:\MAMP\htdocs\labApp\app\routes.py", line 31, in before_request
    if current_user.is_authenticated:
  File "c:\mamp\htdocs\labapp\venv\lib\site-packages\werkzeug\local.py", line 348, in __getattr__
    return getattr(self._get_current_object(), name)
  File "c:\mamp\htdocs\labapp\venv\lib\site-packages\werkzeug\local.py", line 307, in _get_current_object
    return self.__local()
  File "c:\mamp\htdocs\labapp\venv\lib\site-packages\flask_login\utils.py", line 26, in <lambda>
    current_user = LocalProxy(lambda: _get_user())
  File "c:\mamp\htdocs\labapp\venv\lib\site-packages\flask_login\utils.py", line 335, in _get_user
    current_app.login_manager._load_user()
  File "c:\mamp\htdocs\labapp\venv\lib\site-packages\flask_login\login_manager.py", line 359, in _load_user
    return self.reload_user()
  File "c:\mamp\htdocs\labapp\venv\lib\site-packages\flask_login\login_manager.py", line 321, in reload_user
    user = self.user_callback(user_id)
  File "C:\MAMP\htdocs\labApp\app\models.py", line 337, in load_user
    return User.query.get(int(id))
  File "c:\mamp\htdocs\labapp\venv\lib\site-packages\flask_sqlalchemy\__init__.py", line 514, in __get__
    return type.query_class(mapper, session=self.sa.session())
  File "c:\mamp\htdocs\labapp\venv\lib\site-packages\sqlalchemy\orm\scoping.py", line 78, in __call__
    return self.registry()
  File "c:\mamp\htdocs\labapp\venv\lib\site-packages\sqlalchemy\util\_collections.py", line 1032, in __call__
    return self.registry.setdefault(key, self.createfunc())
  File "c:\mamp\htdocs\labapp\venv\lib\site-packages\sqlalchemy\orm\session.py", line 3254, in __call__
    return self.class_(**local_kw)
  File "c:\mamp\htdocs\labapp\venv\lib\site-packages\flask_sqlalchemy\__init__.py", line 143, in __init__
    bind = options.pop('bind', None) or db.engine
  File "c:\mamp\htdocs\labapp\venv\lib\site-packages\flask_sqlalchemy\__init__.py", line 877, in engine
    return self.get_engine()
  File "c:\mamp\htdocs\labapp\venv\lib\site-packages\flask_sqlalchemy\__init__.py", line 896, in get_engine
    return connector.get_engine()
  File "c:\mamp\htdocs\labapp\venv\lib\site-packages\flask_sqlalchemy\__init__.py", line 559, in get_engine
    self._engine = rv = sqlalchemy.create_engine(info, **options)
  File "c:\mamp\htdocs\labapp\venv\lib\site-packages\sqlalchemy\engine\__init__.py", line 479, in create_engine
    return strategy.create(*args, **kwargs)
  File "c:\mamp\htdocs\labapp\venv\lib\site-packages\sqlalchemy\engine\strategies.py", line 87, in create
    dbapi = dialect_cls.dbapi(**dbapi_args)
  File "c:\mamp\htdocs\labapp\venv\lib\site-packages\sqlalchemy\dialects\mysql\pymysql.py", line 62, in dbapi
    return __import__("pymysql")
ModuleNotFoundError: No module named 'pymysql'
2020-04-22 14:16:53,481 ERROR: Exception on /favicon.ico [GET] [in c:\mamp\htdocs\labapp\venv\lib\site-packages\flask\app.py:1892]
Traceback (most recent call last):
  File "c:\mamp\htdocs\labapp\venv\lib\site-packages\sqlalchemy\util\_collections.py", line 1030, in __call__
    return self.registry[key]
KeyError: 14628

During handling of the above exception, another exception occurred:

Traceback (most recent call last):
  File "c:\mamp\htdocs\labapp\venv\lib\site-packages\flask\app.py", line 2447, in wsgi_app
    response = self.full_dispatch_request()
  File "c:\mamp\htdocs\labapp\venv\lib\site-packages\flask\app.py", line 1952, in full_dispatch_request
    rv = self.handle_user_exception(e)
  File "c:\mamp\htdocs\labapp\venv\lib\site-packages\flask_cors\extension.py", line 161, in wrapped_function
    return cors_after_request(app.make_response(f(*args, **kwargs)))
  File "c:\mamp\htdocs\labapp\venv\lib\site-packages\flask\app.py", line 1821, in handle_user_exception
    reraise(exc_type, exc_value, tb)
  File "c:\mamp\htdocs\labapp\venv\lib\site-packages\flask\_compat.py", line 39, in reraise
    raise value
  File "c:\mamp\htdocs\labapp\venv\lib\site-packages\flask\app.py", line 1948, in full_dispatch_request
    rv = self.preprocess_request()
  File "c:\mamp\htdocs\labapp\venv\lib\site-packages\flask\app.py", line 2242, in preprocess_request
    rv = func()
  File "C:\MAMP\htdocs\labApp\app\routes.py", line 31, in before_request
    if current_user.is_authenticated:
  File "c:\mamp\htdocs\labapp\venv\lib\site-packages\werkzeug\local.py", line 348, in __getattr__
    return getattr(self._get_current_object(), name)
  File "c:\mamp\htdocs\labapp\venv\lib\site-packages\werkzeug\local.py", line 307, in _get_current_object
    return self.__local()
  File "c:\mamp\htdocs\labapp\venv\lib\site-packages\flask_login\utils.py", line 26, in <lambda>
    current_user = LocalProxy(lambda: _get_user())
  File "c:\mamp\htdocs\labapp\venv\lib\site-packages\flask_login\utils.py", line 335, in _get_user
    current_app.login_manager._load_user()
  File "c:\mamp\htdocs\labapp\venv\lib\site-packages\flask_login\login_manager.py", line 359, in _load_user
    return self.reload_user()
  File "c:\mamp\htdocs\labapp\venv\lib\site-packages\flask_login\login_manager.py", line 321, in reload_user
    user = self.user_callback(user_id)
  File "C:\MAMP\htdocs\labApp\app\models.py", line 337, in load_user
    return User.query.get(int(id))
  File "c:\mamp\htdocs\labapp\venv\lib\site-packages\flask_sqlalchemy\__init__.py", line 514, in __get__
    return type.query_class(mapper, session=self.sa.session())
  File "c:\mamp\htdocs\labapp\venv\lib\site-packages\sqlalchemy\orm\scoping.py", line 78, in __call__
    return self.registry()
  File "c:\mamp\htdocs\labapp\venv\lib\site-packages\sqlalchemy\util\_collections.py", line 1032, in __call__
    return self.registry.setdefault(key, self.createfunc())
  File "c:\mamp\htdocs\labapp\venv\lib\site-packages\sqlalchemy\orm\session.py", line 3254, in __call__
    return self.class_(**local_kw)
  File "c:\mamp\htdocs\labapp\venv\lib\site-packages\flask_sqlalchemy\__init__.py", line 143, in __init__
    bind = options.pop('bind', None) or db.engine
  File "c:\mamp\htdocs\labapp\venv\lib\site-packages\flask_sqlalchemy\__init__.py", line 877, in engine
    return self.get_engine()
  File "c:\mamp\htdocs\labapp\venv\lib\site-packages\flask_sqlalchemy\__init__.py", line 896, in get_engine
    return connector.get_engine()
  File "c:\mamp\htdocs\labapp\venv\lib\site-packages\flask_sqlalchemy\__init__.py", line 559, in get_engine
    self._engine = rv = sqlalchemy.create_engine(info, **options)
  File "c:\mamp\htdocs\labapp\venv\lib\site-packages\sqlalchemy\engine\__init__.py", line 479, in create_engine
    return strategy.create(*args, **kwargs)
  File "c:\mamp\htdocs\labapp\venv\lib\site-packages\sqlalchemy\engine\strategies.py", line 87, in create
    dbapi = dialect_cls.dbapi(**dbapi_args)
  File "c:\mamp\htdocs\labapp\venv\lib\site-packages\sqlalchemy\dialects\mysql\pymysql.py", line 62, in dbapi
    return __import__("pymysql")
ModuleNotFoundError: No module named 'pymysql'
2020-04-29 12:31:19,016 INFO: labApp startup [in C:\MAMP\htdocs\labApp\app\__init__.py:58]
